<? xml version="1.0"?>
<sdf version='1.7'>
  <model name="flying_quad">
    <pose>0 0 0 0 0 0</pose>
    
    <!-- Main body link -->
    <link name='base_link'>
      <pose>0 0 0 0 0 0</pose>
      <inertial>
        <mass>1.5</mass>
        <inertia>
          <ixx>0.0347563</ixx>
          <ixy>0</ixy>
          <ixz>0</ixz>
          <iyy>0.07</iyy>
          <iyz>0</iyz>
          <izz>0.0977</izz>
        </inertia>
      </inertial>
      
      <!-- Body collision -->
      <collision name='base_collision'>
        <pose>0 0 0 0 0 0</pose>
        <geometry>
          <box>
            <size>0.47 0.47 0.11</size>
          </box>
        </geometry>
      </collision>
      
      <!-- Body visual -->
      <visual name='base_visual'>
        <pose>0 0 0 0 0 0</pose>
        <geometry>
          <box>
            <size>0.47 0.47 0.11</size>
          </box>
        </geometry>
        <material>
          <ambient>0.2 0.2 0.8 1</ambient>
          <diffuse>0.2 0.2 0.8 1</diffuse>
          <specular>0.1 0.1 0.1 1</specular>
        </material>
      </visual>

      <!-- IMU Sensor -->
      <sensor name="imu_sensor" type="imu">
        <always_on>true</always_on>
        <update_rate>100</update_rate>
        <visualize>true</visualize>
        <topic>imu</topic>
        <plugin filename="ignition-gazebo-imu-system" name="ignition::gazebo::systems::Imu">
        </plugin>
      </sensor>

      <!-- GPS Sensor -->
      <sensor name="navsat_sensor" type="navsat">
        <always_on>true</always_on>
        <update_rate>10</update_rate>
        <topic>navsat</topic>
        <plugin filename="ignition-gazebo-navsat-system" name="ignition::gazebo::systems::NavSat">
        </plugin>
      </sensor>
    </link>

    <!-- Motor 1 (Front Right) -->
    <link name='rotor_0'>
      <pose>0.19 -0.19 0.05 0 0 0</pose>
      <inertial>
        <mass>0.005</mass>
        <inertia>
          <ixx>9.75e-07</ixx>
          <ixy>0</ixy>
          <ixz>0</ixz>
          <iyy>4.17041e-05</iyy>
          <iyz>0</iyz>
          <izz>4.26041e-05</izz>
        </inertia>
      </inertial>
      
      <collision name='rotor_0_collision'>
        <pose>0 0 0 0 0 0</pose>
        <geometry>
          <cylinder>
            <length>0.005</length>
            <radius>0.1</radius>
          </cylinder>
        </geometry>
      </collision>
      
      <visual name='rotor_0_visual'>
        <pose>0 0 0 0 0 0</pose>
        <geometry>
          <cylinder>
            <length>0.005</length>
            <radius>0.1</radius>
          </cylinder>
        </geometry>
        <material>
          <ambient>1 0 0 1</ambient>
          <diffuse>1 0 0 1</diffuse>
          <specular>1 0 0 1</specular>
        </material>
      </visual>
    </link>

    <!-- Motor 2 (Back Left) -->
    <link name='rotor_1'>
      <pose>-0.19 0.19 0.05 0 0 0</pose>
      <inertial>
        <mass>0.005</mass>
        <inertia>
          <ixx>9.75e-07</ixx>
          <ixy>0</ixy>
          <ixz>0</ixz>
          <iyy>4.17041e-05</iyy>
          <iyz>0</iyz>
          <izz>4.26041e-05</izz>
        </inertia>
      </inertial>
      
      <collision name='rotor_1_collision'>
        <pose>0 0 0 0 0 0</pose>
        <geometry>
          <cylinder>
            <length>0.005</length>
            <radius>0.1</radius>
          </cylinder>
        </geometry>
      </collision>
      
      <visual name='rotor_1_visual'>
        <pose>0 0 0 0 0 0</pose>
        <geometry>
          <cylinder>
            <length>0.005</length>
            <radius>0.1</radius>
          </cylinder>
        </geometry>
        <material>
          <ambient>0 1 0 1</ambient>
          <diffuse>0 1 0 1</diffuse>
          <specular>0 1 0 1</specular>
        </material>
      </visual>
    </link>

    <!-- Motor 3 (Front Left) -->
    <link name='rotor_2'>
      <pose>0.19 0.19 0.05 0 0 0</pose>
      <inertial>
        <mass>0.005</mass>
        <inertia>
          <ixx>9.75e-07</ixx>
          <ixy>0</ixy>
          <ixz>0</ixz>
          <iyy>4.17041e-05</iyy>
          <iyz>0</iyz>
          <izz>4.26041e-05</izz>
        </inertia>
      </inertial>
      
      <collision name='rotor_2_collision'>
        <pose>0 0 0 0 0 0</pose>
        <geometry>
          <cylinder>
            <length>0.005</length>
            <radius>0.1</radius>
          </cylinder>
        </geometry>
      </collision>
      
      <visual name='rotor_2_visual'>
        <pose>0 0 0 0 0 0</pose>
        <geometry>
          <cylinder>
            <length>0.005</length>
            <radius>0.1</radius>
          </cylinder>
        </geometry>
        <material>
          <ambient>1 1 0 1</ambient>
          <diffuse>1 1 0 1</diffuse>
          <specular>1 1 0 1</specular>
        </material>
      </visual>
    </link>

    <!-- Motor 4 (Back Right) -->
    <link name='rotor_3'>
      <pose>-0.19 -0.19 0.05 0 0 0</pose>
      <inertial>
        <mass>0.005</mass>
        <inertia>
          <ixx>9.75e-07</ixx>
          <ixy>0</ixy>
          <ixz>0</ixz>
          <iyy>4.17041e-05</iyy>
          <iyz>0</iyz>
          <izz>4.26041e-05</izz>
        </inertia>
      </inertial>
      
      <collision name='rotor_3_collision'>
        <pose>0 0 0 0 0 0</pose>
        <geometry>
          <cylinder>
            <length>0.005</length>
            <radius>0.1</radius>
          </cylinder>
        </geometry>
      </collision>
      
      <visual name='rotor_3_visual'>
        <pose>0 0 0 0 0 0</pose>
        <geometry>
          <cylinder>
            <length>0.005</length>
            <radius>0.1</radius>
          </cylinder>
        </geometry>
        <material>
          <ambient>1 0 1 1</ambient>
          <diffuse>1 0 1 1</diffuse>
          <specular>1 0 1 1</specular>
        </material>
      </visual>
    </link>

    <!-- Joints connecting rotors to body -->
    <joint name='rotor_0_joint' type='revolute'>
      <child>rotor_0</child>
      <parent>base_link</parent>
      <axis>
        <xyz>0 0 1</xyz>
        <limit>
          <lower>-1e+16</lower>
          <upper>1e+16</upper>
        </limit>
        <dynamics>
          <spring_reference>0</spring_reference>
          <spring_stiffness>0</spring_stiffness>
        </dynamics>
      </axis>
    </joint>

    <joint name='rotor_1_joint' type='revolute'>
      <child>rotor_1</child>
      <parent>base_link</parent>
      <axis>
        <xyz>0 0 1</xyz>
        <limit>
          <lower>-1e+16</lower>
          <upper>1e+16</upper>
        </limit>
        <dynamics>
          <spring_reference>0</spring_reference>
          <spring_stiffness>0</spring_stiffness>
        </dynamics>
      </axis>
    </joint>

    <joint name='rotor_2_joint' type='revolute'>
      <child>rotor_2</child>
      <parent>base_link</parent>
      <axis>
        <xyz>0 0 1</xyz>
        <limit>
          <lower>-1e+16</lower>
          <upper>1e+16</upper>
        </limit>
        <dynamics>
          <spring_reference>0</spring_reference>
          <spring_stiffness>0</spring_stiffness>
        </dynamics>
      </axis>
    </joint>

    <joint name='rotor_3_joint' type='revolute'>
      <child>rotor_3</child>
      <parent>base_link</parent>
      <axis>
        <xyz>0 0 1</xyz>
        <limit>
          <lower>-1e+16</lower>
          <upper>1e+16</upper>
        </limit>
        <dynamics>
          <spring_reference>0</spring_reference>
          <spring_stiffness>0</spring_stiffness>
        </dynamics>
      </axis>
    </joint>

    <!-- Motor plugins for flight dynamics -->
    <plugin filename="ignition-gazebo-multicopter-motor-model-system" name="ignition::gazebo::systems::MulticopterMotorModel">
      <jointName>rotor_0_joint</jointName>
      <linkName>rotor_0</linkName>
      <turningDirection>ccw</turningDirection>
      <timeConstantUp>0.0125</timeConstantUp>
      <timeConstantDown>0.025</timeConstantDown>
      <maxRotVelocity>800.0</maxRotVelocity>
      <motorConstant>8.54858e-06</motorConstant>
      <momentConstant>0. 016</momentConstant>
      <commandSubTopic>command/motor_speed</commandSubTopic>
      <motorNumber>0</motorNumber>
      <rotorDragCoefficient>8.06428e-05</rotorDragCoefficient>
      <rollingMomentCoefficient>1e-06</rollingMomentCoefficient>
      <motorSpeedPubTopic>motor_speed/0</motorSpeedPubTopic>
      <rotorVelocitySlowdownSim>10</rotorVelocitySlowdownSim>
      <motorType>velocity</motorType>
    </plugin>

    <plugin filename="ignition-gazebo-multicopter-motor-model-system" name="ignition::gazebo::systems::MulticopterMotorModel">
      <jointName>rotor_1_joint</jointName>
      <linkName>rotor_1</linkName>
      <turningDirection>ccw</turningDirection>
      <timeConstantUp>0.0125</timeConstantUp>
      <timeConstantDown>0. 025</timeConstantDown>
      <maxRotVelocity>800.0</maxRotVelocity>
      <motorConstant>8.54858e-06</motorConstant>
      <momentConstant>0.016</momentConstant>
      <commandSubTopic>command/motor_speed</commandSubTopic>
      <motorNumber>1</motorNumber>
      <rotorDragCoefficient>8. 06428e-05</rotorDragCoefficient>
      <rollingMomentCoefficient>1e-06</rollingMomentCoefficient>
      <motorSpeedPubTopic>motor_speed/1</motorSpeedPubTopic>
      <rotorVelocitySlowdownSim>10</rotorVelocitySlowdownSim>
      <motorType>velocity</motorType>
    </plugin>

    <plugin filename="ignition-gazebo-multicopter-motor-model-system" name="ignition::gazebo::systems::MulticopterMotorModel">
      <jointName>rotor_2_joint</jointName>
      <linkName>rotor_2</linkName>
      <turningDirection>cw</turningDirection>
      <timeConstantUp>0.0125</timeConstantUp>
      <timeConstantDown>0.025</timeConstantDown>
      <maxRotVelocity>800.0</maxRotVelocity>
      <motorConstant>8.54858e-06</motorConstant>
      <momentConstant>0.016</momentConstant>
      <commandSubTopic>command/motor_speed</commandSubTopic>
      <motorNumber>2</motorNumber>
      <rotorDragCoefficient>8.06428e-05</rotorDragCoefficient>
      <rollingMomentCoefficient>1e-06</rollingMomentCoefficient>
      <motorSpeedPubTopic>motor_speed/2</motorSpeedPubTopic>
      <rotorVelocitySlowdownSim>10</rotorVelocitySlowdownSim>
      <motorType>velocity</motorType>
    </plugin>

    <plugin filename="ignition-gazebo-multicopter-motor-model-system" name="ignition::gazebo::systems::MulticopterMotorModel">
      <jointName>rotor_3_joint</jointName>
      <linkName>rotor_3</linkName>
      <turningDirection>cw</turningDirection>
      <timeConstantUp>0.0125</timeConstantUp>
      <timeConstantDown>0.025</timeConstantDown>
      <maxRotVelocity>800.0</maxRotVelocity>
      <motorConstant>8.54858e-06</motorConstant>
      <momentConstant>0.016</momentConstant>
      <commandSubTopic>command/motor_speed</commandSubTopic>
      <motorNumber>3</motorNumber>
      <rotorDragCoefficient>8.06428e-05</rotorDragCoefficient>
      <rollingMomentCoefficient>1e-06</rollingMomentCoefficient>
      <motorSpeedPubTopic>motor_speed/3</motorSpeedPubTopic>
      <rotorVelocitySlowdownSim>10</rotorVelocitySlowdownSim>
      <motorType>velocity</motorType>
    </plugin>

    <!-- Odometry plugin -->
    <plugin filename="ignition-gazebo-odometry-publisher-system" name="ignition::gazebo::systems::OdometryPublisher">
      <odom_frame>odom</odom_frame>
      <robot_base_frame>base_link</robot_base_frame>
      <dimensions>3</dimensions>
      <odom_publish_frequency>50</odom_publish_frequency>
    </plugin>

    <!-- Pose publisher for position feedback -->
    <plugin filename="ignition-gazebo-pose-publisher-system" name="ignition::gazebo::systems::PosePublisher">
      <publish_link_pose>true</publish_link_pose>
      <use_pose_vector_msg>true</use_pose_vector_msg>
      <static_publisher>true</static_publisher>
      <static_update_frequency>50</static_update_frequency>
    </plugin>
  </model>
</sdf>